<sdf version='1.7'>
  <world name='default'>
    <light name='sun' type='directional'>
      <cast_shadows>1</cast_shadows>
      <pose>0 0 10 0 -0 0</pose>
      <diffuse>0.8 0.8 0.8 1</diffuse>
      <specular>0.2 0.2 0.2 1</specular>
      <attenuation>
        <range>1000</range>
        <constant>0.9</constant>
        <linear>0.01</linear>
        <quadratic>0.001</quadratic>
      </attenuation>
      <direction>-0.5 0.1 -0.9</direction>
    </light>
    <model name='ground_plane'>
      <static>1</static>
      <link name='link'>
        <collision name='collision'>
          <geometry>
            <plane>
              <normal>0 0 1</normal>
              <size>100 100</size>
            </plane>
          </geometry>
          <surface>
            <contact>
              <collide_bitmask>65535</collide_bitmask>
              <ode/>
            </contact>
            <friction>
              <ode>
                <mu>100</mu>
                <mu2>50</mu2>
              </ode>
              <torsional>
                <ode/>
              </torsional>
            </friction>
            <bounce/>
          </surface>
          <max_contacts>10</max_contacts>
        </collision>
        <visual name='visual'>
          <cast_shadows>0</cast_shadows>
          <geometry>
            <plane>
              <normal>0 0 1</normal>
              <size>100 100</size>
            </plane>
          </geometry>
          <material>
            <script>
              <uri>file://media/materials/scripts/gazebo.material</uri>
              <name>Gazebo/Grey</name>
            </script>
          </material>
        </visual>
        <self_collide>0</self_collide>
        <enable_wind>0</enable_wind>
        <kinematic>0</kinematic>
      </link>
    </model>
    <gravity>0 0 -9.8</gravity>
    <magnetic_field>6e-06 2.3e-05 -4.2e-05</magnetic_field>
    <atmosphere type='adiabatic'/>
    <physics type='ode'>
      <max_step_size>0.001</max_step_size>
      <real_time_factor>1</real_time_factor>
      <real_time_update_rate>1000</real_time_update_rate>
    </physics>
    <scene>
      <ambient>0.4 0.4 0.4 1</ambient>
      <background>0.7 0.7 0.7 1</background>
      <shadows>1</shadows>
    </scene>
    <wind/>
    <spherical_coordinates>
      <surface_model>EARTH_WGS84</surface_model>
      <latitude_deg>0</latitude_deg>
      <longitude_deg>0</longitude_deg>
      <elevation>0</elevation>
      <heading_deg>0</heading_deg>
    </spherical_coordinates>
    <model name='/'>
      <link name='base_link'>
        <inertial>
          <pose>-0.000628 -0.085279 0.071891 0 -0 0</pose>
          <mass>47.714</mass>
          <inertia>
            <ixx>0.74964</ixx>
            <ixy>-0.0236362</ixy>
            <ixz>-0.119985</ixz>
            <iyy>1.87163</iyy>
            <iyz>-0.00463628</iyz>
            <izz>2.04623</izz>
          </inertia>
        </inertial>
        <collision name='base_link_collision'>
          <pose>0 0 0.061875 0 -0 0</pose>
          <geometry>
            <box>
              <size>0.9874 0.5709 0.12375</size>
            </box>
          </geometry>
          <surface>
            <contact>
              <ode/>
            </contact>
            <bounce/>
            <friction>
              <torsional>
                <ode/>
              </torsional>
              <ode/>
            </friction>
          </surface>
          <max_contacts>10</max_contacts>
        </collision>
        <collision name='base_link_collision_1'>
          <pose>0 0 0.175625 0 -0 0</pose>
          <geometry>
            <box>
              <size>0.78992 0.5709 0.10375</size>
            </box>
          </geometry>
          <surface>
            <contact>
              <ode/>
            </contact>
            <bounce/>
            <friction>
              <torsional>
                <ode/>
              </torsional>
              <ode/>
            </friction>
          </surface>
          <max_contacts>10</max_contacts>
        </collision>
        <collision name='base_link_fixed_joint_lump__top_plate_link_collision_2'>
          <pose>0.0812 0 0.245 0 -0 0</pose>
          <geometry>
            <mesh>
              <scale>1 1 1</scale>
              <uri>/home/m/catkin_ws/src/husky_description/meshes/top_plate.stl</uri>
            </mesh>
          </geometry>
          <surface>
            <contact>
              <ode/>
            </contact>
            <bounce/>
            <friction>
              <torsional>
                <ode/>
              </torsional>
              <ode/>
            </friction>
          </surface>
          <max_contacts>10</max_contacts>
        </collision>
        <collision name='base_link_fixed_joint_lump__vlp201_base_link_collision_3'>
          <pose>0 0 0.38585 0 -0 0</pose>
          <geometry>
            <cylinder>
              <length>0.0717</length>
              <radius>0.0516</radius>
            </cylinder>
          </geometry>
          <surface>
            <contact>
              <ode/>
            </contact>
            <bounce/>
            <friction>
              <torsional>
                <ode/>
              </torsional>
              <ode/>
            </friction>
          </surface>
          <max_contacts>10</max_contacts>
        </collision>
        <collision name='base_link_fixed_joint_lump__vlp202_base_link_collision_4'>
          <pose>-5.7e-05 -0.18585 0.299971 1.57159 0.001593 -0.001593</pose>
          <geometry>
            <cylinder>
              <length>0.0717</length>
              <radius>0.0516</radius>
            </cylinder>
          </geometry>
          <surface>
            <contact>
              <ode/>
            </contact>
            <bounce/>
            <friction>
              <torsional>
                <ode/>
              </torsional>
              <ode/>
            </friction>
          </surface>
          <max_contacts>10</max_contacts>
        </collision>
        <visual name='base_link_visual'>
          <pose>0 0 0 0 -0 0</pose>
          <geometry>
            <mesh>
              <scale>1 1 1</scale>
              <uri>/home/m/catkin_ws/src/husky_description/meshes/base_link.dae</uri>
            </mesh>
          </geometry>
        </visual>
        <visual name='base_link_fixed_joint_lump__front_bumper_link_visual_1'>
          <pose>0.48 0 0.091 0 -0 0</pose>
          <geometry>
            <mesh>
              <scale>1 1 1</scale>
              <uri>/home/m/catkin_ws/src/husky_description/meshes/bumper.dae</uri>
            </mesh>
          </geometry>
        </visual>
        <visual name='base_link_fixed_joint_lump__rear_bumper_link_visual_2'>
          <pose>-0.48 0 0.091 0 -0 3.14159</pose>
          <geometry>
            <mesh>
              <scale>1 1 1</scale>
              <uri>/home/m/catkin_ws/src/husky_description/meshes/bumper.dae</uri>
            </mesh>
          </geometry>
        </visual>
        <visual name='base_link_fixed_joint_lump__top_chassis_link_visual_3'>
          <pose>0 0 0 0 -0 0</pose>
          <geometry>
            <mesh>
              <scale>1 1 1</scale>
              <uri>/home/m/catkin_ws/src/husky_description/meshes/top_chassis.dae</uri>
            </mesh>
          </geometry>
        </visual>
        <visual name='base_link_fixed_joint_lump__top_plate_link_visual_4'>
          <pose>0.0812 0 0.245 0 -0 0</pose>
          <geometry>
            <mesh>
              <scale>1 1 1</scale>
              <uri>/home/m/catkin_ws/src/husky_description/meshes/top_plate.dae</uri>
            </mesh>
          </geometry>
        </visual>
        <visual name='base_link_fixed_joint_lump__user_rail_link_visual_5'>
          <pose>0.272 0 0.245 0 -0 0</pose>
          <geometry>
            <mesh>
              <scale>1 1 1</scale>
              <uri>/home/m/catkin_ws/src/husky_description/meshes/user_rail.dae</uri>
            </mesh>
          </geometry>
        </visual>
        <visual name='base_link_fixed_joint_lump__vlp201_base_link_visual_6'>
          <pose>0 0 0.35 0 -0 0</pose>
          <geometry>
            <mesh>
              <scale>1 1 1</scale>
              <uri>/home/m/catkin_ws/src/velodyne_description/meshes/VLP16_base_1.dae</uri>
            </mesh>
          </geometry>
        </visual>
        <visual name='base_link_fixed_joint_lump__vlp201_base_link_visual_7'>
          <pose>0 0 0.35 0 -0 0</pose>
          <geometry>
            <mesh>
              <scale>1 1 1</scale>
              <uri>/home/m/catkin_ws/src/velodyne_description/meshes/VLP16_base_2.dae</uri>
            </mesh>
          </geometry>
        </visual>
        <visual name='base_link_fixed_joint_lump__vlp201_visual_8'>
          <pose>0 0 0.35 0 -0 0</pose>
          <geometry>
            <mesh>
              <scale>1 1 1</scale>
              <uri>/home/m/catkin_ws/src/velodyne_description/meshes/VLP16_scan.dae</uri>
            </mesh>
          </geometry>
        </visual>
        <visual name='base_link_fixed_joint_lump__vlp202_base_link_visual_9'>
          <pose>0 -0.15 0.3 1.57159 0.001593 -0.001593</pose>
          <geometry>
            <mesh>
              <scale>1 1 1</scale>
              <uri>/home/m/catkin_ws/src/velodyne_description/meshes/VLP16_base_1.dae</uri>
            </mesh>
          </geometry>
        </visual>
        <visual name='base_link_fixed_joint_lump__vlp202_base_link_visual_10'>
          <pose>0 -0.15 0.3 1.57159 0.001593 -0.001593</pose>
          <geometry>
            <mesh>
              <scale>1 1 1</scale>
              <uri>/home/m/catkin_ws/src/velodyne_description/meshes/VLP16_base_2.dae</uri>
            </mesh>
          </geometry>
        </visual>
        <visual name='base_link_fixed_joint_lump__vlp202_visual_11'>
          <pose>0 -0.15 0.3 1.57159 0.001593 -0.001593</pose>
          <geometry>
            <mesh>
              <scale>1 1 1</scale>
              <uri>/home/m/catkin_ws/src/velodyne_description/meshes/VLP16_scan.dae</uri>
            </mesh>
          </geometry>
        </visual>
        <velocity_decay/>
        <velocity_decay/>
        <sensor name='vlp201-VLP16' type='ray'>
          <visualize>0</visualize>
          <update_rate>10</update_rate>
          <ray>
            <scan>
              <horizontal>
                <samples>440</samples>
                <resolution>1</resolution>
                <min_angle>-3.14159</min_angle>
                <max_angle>3.14159</max_angle>
              </horizontal>
              <vertical>
                <samples>16</samples>
                <resolution>1</resolution>
                <min_angle>-0.261799</min_angle>
                <max_angle>0.261799</max_angle>
              </vertical>
            </scan>
            <range>
              <min>0.3</min>
              <max>131</max>
              <resolution>0.001</resolution>
            </range>
            <noise>
              <type>gaussian</type>
              <mean>0</mean>
              <stddev>0</stddev>
            </noise>
          </ray>
          <plugin name='gazebo_ros_laser_controller' filename='libgazebo_ros_velodyne_laser.so'>
            <topicName>/vlp_1/velodyne_points</topicName>
            <frameName>vlp201</frameName>
            <min_range>0.9</min_range>
            <max_range>130.0</max_range>
            <gaussianNoise>0.008</gaussianNoise>
            <robotNamespace>/</robotNamespace>
          </plugin>
          <pose>0 0 0.3877 0 -0 0</pose>
        </sensor>
        <gravity>1</gravity>
        <velocity_decay/>
        <sensor name='vlp202-VLP16' type='ray'>
          <visualize>0</visualize>
          <update_rate>10</update_rate>
          <ray>
            <scan>
              <horizontal>
                <samples>440</samples>
                <resolution>1</resolution>
                <min_angle>-3.14159</min_angle>
                <max_angle>3.14159</max_angle>
              </horizontal>
              <vertical>
                <samples>16</samples>
                <resolution>1</resolution>
                <min_angle>-0.261799</min_angle>
                <max_angle>0.261799</max_angle>
              </vertical>
            </scan>
            <range>
              <min>0.3</min>
              <max>131</max>
              <resolution>0.001</resolution>
            </range>
            <noise>
              <type>gaussian</type>
              <mean>0</mean>
              <stddev>0</stddev>
            </noise>
          </ray>
          <plugin name='gazebo_ros_laser_controller' filename='libgazebo_ros_velodyne_laser.so'>
            <topicName>/vlp_2/velodyne_points</topicName>
            <frameName>vlp202</frameName>
            <min_range>0.9</min_range>
            <max_range>130.0</max_range>
            <gaussianNoise>0.008</gaussianNoise>
            <robotNamespace>/</robotNamespace>
          </plugin>
          <pose>-6e-05 -0.1877 0.29997 1.57159 0.001593 -0.001593</pose>
        </sensor>
        <self_collide>0</self_collide>
        <enable_wind>0</enable_wind>
        <kinematic>0</kinematic>
      </link>
      <joint name='front_left_wheel' type='revolute'>
        <pose relative_to='base_link'>0.256 0.2854 0.03282 0 -0 0</pose>
        <parent>base_link</parent>
        <child>front_left_wheel_link</child>
        <axis>
          <xyz>0 1 0</xyz>
          <limit>
            <lower>-1e+16</lower>
            <upper>1e+16</upper>
          </limit>
          <dynamics>
            <spring_reference>0</spring_reference>
            <spring_stiffness>0</spring_stiffness>
          </dynamics>
        </axis>
      </joint>
      <link name='front_left_wheel_link'>
        <pose relative_to='front_left_wheel'>0 0 0 0 -0 0</pose>
        <inertial>
          <pose>0 0 0 0 -0 0</pose>
          <mass>2.637</mass>
          <inertia>
            <ixx>0.02467</ixx>
            <ixy>0</ixy>
            <ixz>0</ixz>
            <iyy>0.04411</iyy>
            <iyz>0</iyz>
            <izz>0.02467</izz>
          </inertia>
        </inertial>
        <collision name='front_left_wheel_link_collision'>
          <pose>0 0 0 1.57079 -0 0</pose>
          <geometry>
            <cylinder>
              <length>0.1143</length>
              <radius>0.1651</radius>
            </cylinder>
          </geometry>
          <surface>
            <contact>
              <ode>
                <kp>1e+07</kp>
                <kd>1</kd>
              </ode>
            </contact>
            <friction>
              <ode>
                <mu>1</mu>
                <mu2>1</mu2>
                <fdir1>1 0 0</fdir1>
              </ode>
              <torsional>
                <ode/>
              </torsional>
            </friction>
            <bounce/>
          </surface>
          <max_contacts>10</max_contacts>
        </collision>
        <visual name='front_left_wheel_link_visual'>
          <pose>0 0 0 0 -0 0</pose>
          <geometry>
            <mesh>
              <scale>1 1 1</scale>
              <uri>/home/m/catkin_ws/src/husky_description/meshes/wheel.dae</uri>
            </mesh>
          </geometry>
        </visual>
        <gravity>1</gravity>
        <velocity_decay/>
        <self_collide>0</self_collide>
        <enable_wind>0</enable_wind>
        <kinematic>0</kinematic>
      </link>
      <joint name='front_right_wheel' type='revolute'>
        <pose relative_to='base_link'>0.256 -0.2854 0.03282 0 -0 0</pose>
        <parent>base_link</parent>
        <child>front_right_wheel_link</child>
        <axis>
          <xyz>0 1 0</xyz>
          <limit>
            <lower>-1e+16</lower>
            <upper>1e+16</upper>
          </limit>
          <dynamics>
            <spring_reference>0</spring_reference>
            <spring_stiffness>0</spring_stiffness>
          </dynamics>
        </axis>
      </joint>
      <link name='front_right_wheel_link'>
        <pose relative_to='front_right_wheel'>0 0 0 0 -0 0</pose>
        <inertial>
          <pose>0 0 0 0 -0 0</pose>
          <mass>2.637</mass>
          <inertia>
            <ixx>0.02467</ixx>
            <ixy>0</ixy>
            <ixz>0</ixz>
            <iyy>0.04411</iyy>
            <iyz>0</iyz>
            <izz>0.02467</izz>
          </inertia>
        </inertial>
        <collision name='front_right_wheel_link_collision'>
          <pose>0 0 0 1.57079 -0 0</pose>
          <geometry>
            <cylinder>
              <length>0.1143</length>
              <radius>0.1651</radius>
            </cylinder>
          </geometry>
          <surface>
            <contact>
              <ode>
                <kp>1e+07</kp>
                <kd>1</kd>
              </ode>
            </contact>
            <friction>
              <ode>
                <mu>1</mu>
                <mu2>1</mu2>
                <fdir1>1 0 0</fdir1>
              </ode>
              <torsional>
                <ode/>
              </torsional>
            </friction>
            <bounce/>
          </surface>
          <max_contacts>10</max_contacts>
        </collision>
        <visual name='front_right_wheel_link_visual'>
          <pose>0 0 0 0 -0 0</pose>
          <geometry>
            <mesh>
              <scale>1 1 1</scale>
              <uri>/home/m/catkin_ws/src/husky_description/meshes/wheel.dae</uri>
            </mesh>
          </geometry>
        </visual>
        <gravity>1</gravity>
        <velocity_decay/>
        <self_collide>0</self_collide>
        <enable_wind>0</enable_wind>
        <kinematic>0</kinematic>
      </link>
      <joint name='rear_left_wheel' type='revolute'>
        <pose relative_to='base_link'>-0.256 0.2854 0.03282 0 -0 0</pose>
        <parent>base_link</parent>
        <child>rear_left_wheel_link</child>
        <axis>
          <xyz>0 1 0</xyz>
          <limit>
            <lower>-1e+16</lower>
            <upper>1e+16</upper>
          </limit>
          <dynamics>
            <spring_reference>0</spring_reference>
            <spring_stiffness>0</spring_stiffness>
          </dynamics>
        </axis>
      </joint>
      <link name='rear_left_wheel_link'>
        <pose relative_to='rear_left_wheel'>0 0 0 0 -0 0</pose>
        <inertial>
          <pose>0 0 0 0 -0 0</pose>
          <mass>2.637</mass>
          <inertia>
            <ixx>0.02467</ixx>
            <ixy>0</ixy>
            <ixz>0</ixz>
            <iyy>0.04411</iyy>
            <iyz>0</iyz>
            <izz>0.02467</izz>
          </inertia>
        </inertial>
        <collision name='rear_left_wheel_link_collision'>
          <pose>0 0 0 1.57079 -0 0</pose>
          <geometry>
            <cylinder>
              <length>0.1143</length>
              <radius>0.1651</radius>
            </cylinder>
          </geometry>
          <surface>
            <contact>
              <ode>
                <kp>1e+07</kp>
                <kd>1</kd>
              </ode>
            </contact>
            <friction>
              <ode>
                <mu>1</mu>
                <mu2>1</mu2>
                <fdir1>1 0 0</fdir1>
              </ode>
              <torsional>
                <ode/>
              </torsional>
            </friction>
            <bounce/>
          </surface>
          <max_contacts>10</max_contacts>
        </collision>
        <visual name='rear_left_wheel_link_visual'>
          <pose>0 0 0 0 -0 0</pose>
          <geometry>
            <mesh>
              <scale>1 1 1</scale>
              <uri>/home/m/catkin_ws/src/husky_description/meshes/wheel.dae</uri>
            </mesh>
          </geometry>
        </visual>
        <gravity>1</gravity>
        <velocity_decay/>
        <self_collide>0</self_collide>
        <enable_wind>0</enable_wind>
        <kinematic>0</kinematic>
      </link>
      <joint name='rear_right_wheel' type='revolute'>
        <pose relative_to='base_link'>-0.256 -0.2854 0.03282 0 -0 0</pose>
        <parent>base_link</parent>
        <child>rear_right_wheel_link</child>
        <axis>
          <xyz>0 1 0</xyz>
          <limit>
            <lower>-1e+16</lower>
            <upper>1e+16</upper>
          </limit>
          <dynamics>
            <spring_reference>0</spring_reference>
            <spring_stiffness>0</spring_stiffness>
          </dynamics>
        </axis>
      </joint>
      <link name='rear_right_wheel_link'>
        <pose relative_to='rear_right_wheel'>0 0 0 0 -0 0</pose>
        <inertial>
          <pose>0 0 0 0 -0 0</pose>
          <mass>2.637</mass>
          <inertia>
            <ixx>0.02467</ixx>
            <ixy>0</ixy>
            <ixz>0</ixz>
            <iyy>0.04411</iyy>
            <iyz>0</iyz>
            <izz>0.02467</izz>
          </inertia>
        </inertial>
        <collision name='rear_right_wheel_link_collision'>
          <pose>0 0 0 1.57079 -0 0</pose>
          <geometry>
            <cylinder>
              <length>0.1143</length>
              <radius>0.1651</radius>
            </cylinder>
          </geometry>
          <surface>
            <contact>
              <ode>
                <kp>1e+07</kp>
                <kd>1</kd>
              </ode>
            </contact>
            <friction>
              <ode>
                <mu>1</mu>
                <mu2>1</mu2>
                <fdir1>1 0 0</fdir1>
              </ode>
              <torsional>
                <ode/>
              </torsional>
            </friction>
            <bounce/>
          </surface>
          <max_contacts>10</max_contacts>
        </collision>
        <visual name='rear_right_wheel_link_visual'>
          <pose>0 0 0 0 -0 0</pose>
          <geometry>
            <mesh>
              <scale>1 1 1</scale>
              <uri>/home/m/catkin_ws/src/husky_description/meshes/wheel.dae</uri>
            </mesh>
          </geometry>
        </visual>
        <gravity>1</gravity>
        <velocity_decay/>
        <self_collide>0</self_collide>
        <enable_wind>0</enable_wind>
        <kinematic>0</kinematic>
      </link>
      <plugin name='gazebo_ros_control' filename='libgazebo_ros_control.so'>
        <robotNamespace>/</robotNamespace>
        <legacyModeNS>1</legacyModeNS>
      </plugin>
      <plugin name='imu_controller' filename='libhector_gazebo_ros_imu.so'>
        <robotNamespace>/</robotNamespace>
        <updateRate>50.0</updateRate>
        <bodyName>base_link</bodyName>
        <topicName>imu/data</topicName>
        <accelDrift>0.005 0.005 0.005</accelDrift>
        <accelGaussianNoise>0.005 0.005 0.005</accelGaussianNoise>
        <rateDrift>0.005 0.005 0.005</rateDrift>
        <rateGaussianNoise>0.005 0.005 0.005</rateGaussianNoise>
        <headingDrift>0.005</headingDrift>
        <headingGaussianNoise>0.005</headingGaussianNoise>
      </plugin>
      <static>0</static>
      <plugin name='gps_controller' filename='libhector_gazebo_ros_gps.so'>
        <robotNamespace>/</robotNamespace>
        <updateRate>40</updateRate>
        <bodyName>base_link</bodyName>
        <frameId>base_link</frameId>
        <topicName>navsat/fix</topicName>
        <velocityTopicName>navsat/vel</velocityTopicName>
        <referenceLatitude>49.9</referenceLatitude>
        <referenceLongitude>8.9</referenceLongitude>
        <referenceHeading>0</referenceHeading>
        <referenceAltitude>0</referenceAltitude>
        <drift>0.0001 0.0001 0.0001</drift>
      </plugin>
      <pose>0 0 0 0 -0 0</pose>
    </model>
    <state world_name='default'>
      <sim_time>88 42000000</sim_time>
      <real_time>91 835639820</real_time>
      <wall_time>1599609340 497412364</wall_time>
      <iterations>88042</iterations>
      <model name='/'>
        <pose>0.306668 -0.123203 0.132273 6e-06 0 -0.07953</pose>
        <scale>1 1 1</scale>
        <link name='base_link'>
          <pose>0.306668 -0.123203 0.132273 6e-06 0 -0.07953</pose>
          <velocity>-1.3e-05 -1.6e-05 -2e-06 0.000182 0.000201 -2.7e-05</velocity>
          <acceleration>1e-06 1e-06 2e-06 -8e-06 -8e-06 1e-06</acceleration>
          <wrench>6.4e-05 5.9e-05 0.000113 0 -0 0</wrench>
        </link>
        <link name='front_left_wheel_link'>
          <pose>0.584532 0.140955 0.165095 -1.9e-05 -0.608065 -0.079517</pose>
          <velocity>1e-06 -2.7e-05 -9e-06 0.000157 -2.8e-05 5e-05</velocity>
          <acceleration>1e-06 1e-06 2e-06 0.003248 -9.9e-05 -3e-06</acceleration>
          <wrench>3e-06 3e-06 5e-06 0 -0 0</wrench>
        </link>
        <link name='front_right_wheel_link'>
          <pose>0.539185 -0.428038 0.165091 3.14152 -1.16576 3.06213</pose>
          <velocity>-1.4e-05 -2.1e-05 -0.000104 0.000232 0.001373 -9.8e-05</velocity>
          <acceleration>2e-06 1e-06 6e-06 -0.016611 0.000507 -2e-06</acceleration>
          <wrench>5e-06 2e-06 1.6e-05 0 -0 0</wrench>
        </link>
        <link name='rear_left_wheel_link'>
          <pose>0.074151 0.181633 0.165095 3.14158 -0.633248 3.06207</pose>
          <velocity>2e-06 -1.8e-05 0.0001 7.2e-05 -0.000435 -5.7e-05</velocity>
          <acceleration>1e-06 1e-06 -3e-06 0.009084 -0.000299 4e-06</acceleration>
          <wrench>3e-06 2e-06 -7e-06 0 -0 0</wrench>
        </link>
        <link name='rear_right_wheel_link'>
          <pose>0.028803 -0.387363 0.165091 3.14159 -0.312217 3.06206</pose>
          <velocity>-1.4e-05 -1.7e-05 5e-06 0.000105 -9.6e-05 -3.4e-05</velocity>
          <acceleration>2e-06 1e-06 2e-06 0.004264 -0.000141 2e-06</acceleration>
          <wrench>5e-06 2e-06 4e-06 0 -0 0</wrench>
        </link>
      </model>
      <model name='ground_plane'>
        <pose>0 0 0 0 -0 0</pose>
        <scale>1 1 1</scale>
        <link name='link'>
          <pose>0 0 0 0 -0 0</pose>
          <velocity>0 0 0 0 -0 0</velocity>
          <acceleration>0 0 0 0 -0 0</acceleration>
          <wrench>0 0 0 0 -0 0</wrench>
        </link>
      </model>
      <light name='sun'>
        <pose>0 0 10 0 -0 0</pose>
      </light>
    </state>
    <gui fullscreen='0'>
      <camera name='user_camera'>
        <pose>-5.94787 0.055296 4.32803 0 0.647642 0.457019</pose>
        <view_controller>orbit</view_controller>
        <projection_type>perspective</projection_type>
      </camera>
    </gui>
  </world>
</sdf>
